Workbook

Sheet RESUMEN 2022-2
D1: SEDE | E1: FACULTAD | F1: PROGRAMA | G1: NÚMERO DE PRACTICAS
G2: TEORICO | H2: TEORICO PRACTICO | I2: PRACTICO | J2: PRACTICA PEDAGOGICA | K2: TOTAL POR FACULTAD | M2: FACULTAD | N2: Total
A3: CARACTER DE LOS CURSOS CON SOLICITUD PRÁCTICAS EXTRAMUROS | D3: NEIVA | E3: EDUCACIÓN | F3: LICENCIATURA EN EDUCACIÓN ARTÍSTICA | H3: 3 | K3: 45 | M3: EDUCACIÓN | N3: =K3 -> 45
A4: TEORICO | B4: =G26 -> 30 | D4: NEIVA | M4: CIENCIAS SOCIALES Y HUMANAS | N4: =K12 -> 15
A5: TEORICO PRACTICO | B5: =H26 -> 181 | D5: NEIVA | F5: LICENCIATURA EN EDUCACIÓN INFANTIL | G5: 1 | M5: CIENCIAS JURIDICAS Y POLITICAS | N5: =K16 -> 2
A6: PRACTICO | B6: 1 | D6: NEIVA | F6: LICENCIATURA EN CIENCIAS NATURALES Y EDUCACIÓN AMBIENTAL | G6: 9 | H6: 7 | M6: INGENIERIA | N6: =K17 -> 125
A7: PRACTICA PEDAGOGICA | B7: 1 | D7: NEIVA | F7: LICENCIATURA EN CIENCIAS SOCIALES | H7: 4 | M7: CIENCIAS EXACTAS Y NATURALES | N7: =K25 -> 26
B8: =SUM(B4:B7) -> 213 | D8: NEIVA | F8: LICENCIATURA EN MATEMATICAS | G8: 1 | H8: 7 | M8: ECONOMÍA Y ADMINISTRACIÓN | N8: 0
D9: NEIVA | F9: LICENCIATURA EN LITERATURA Y LENGUA CASTELLANA | J9: 1 | M9: SALUD | N9: 0
D10: NEIVA | F10: LICENCIATURA EN EDUCACIÓN FISICA, RECREACIÓN Y DEPORTES | H10: 5 | M10: TOTALES | N10: 213
D11: NEIVA | F11: DEPARTAMENTO DE PSICOPEDAGOGIA | G11: 5 | H11: 2
D12: NEIVA | E12: CIENCIAS SOCIALES Y HUMANAS | F12: ANTROPOLOGIA | H12: 5 | K12: 15
D13: PITALITO | F13: COMUNICACIÓN SOCIAL Y PERIODISMO | G13: 1 | H13: 1
D14: NEIVA | F14: COMUNICACIÓN SOCIAL Y PERIODISMO | G14: 2 | H14: 4
D15: NEIVA | F15: PSICOLOGÍA | G15: 1 | H15: 1
D16: NEIVA | E16: CIENCIAS JURIDICAS Y POLITICAS | F16: CIENCIA POLITICA | G16: 2 | K16: =G16 -> 2
D17: NEIVA | E17: INGENIERIA | F17: INGENIERÍA AGROINDUSTRIAL | H17: 9 | K17: 125
D18: GARZÓN | F18: INGENIERÍA AGRÍCOLA | G18: 3 | H18: 29 | I18: 1
D19: LA PLATA | F19: INGENIERÍA AGRÍCOLA | H19: 30
D20: PITALITO | F20: INGENIERÍA AGRÍCOLA | G20: 2 | H20: 16
D21: NEIVA | F21: INGENIERÍA AGRÍCOLA | G21: 2 | H21: 19
D22: NEIVA | F22: INGENIERÍA ELECTRÓNICA | H22: 1
D23: NEIVA | F23: INGENIERÍA CIVIL | G23: 1 | H23: 5
D24: NEIVA | F24: INGENIERÍA DE PETROLEOS | H24: 7
D25: NEIVA | E25: CIENCIAS EXACTAS Y NATURALES | F25: BIOLOGIA APLICADA | H25: 26 | K25: 26
F26: TOTALES | G26: =SUM(G3:G25) -> 30 | H26: =SUM(H3:H25) -> 181 | I26: =SUM(I3:I25) -> 1 | J26: =SUM(J3:J25) -> 1 | K26: =SUM(K3:K25) -> 213
B31: Nota: | C31: 7 Eliminadas por ajuste del programa de Lic Ciencias Naturales y Educación Ambiental
C32: Eliminación del número de días de las prácticas del Programa de Lic en Educación Física, Recreación y Deportes
C35: No. de solicitudes | D35: COMBUSTIBLE | E35: PEAJES | F35: PARQUEADERO | G35: IMPREVISTOS | H35: VALOR BUS EXTERNO | I35: COSTO TOTAL DÍAS VIATICOS DOCENTES | J35: TOTAL
A36: CONSOLIDADO | C36: 213 | D36: $22.730.000 | E36: $11.515.000 | F36: $2.815.000 | G36: 0 | H36: $481.370.000 | I36: $73.729.514 | J36: $592.159.514
A37: TEORICO-PRACTICO | C37: 162 | D37: $20.880.000 | E37: $10.783.000 | F37: $2.620.000 | G37: 0 | H37: $382.240.000 | I37: $62.569.514 | J37: $479.092.514
A38: TEORICO | C38: 29 | D38: $1.850.000 | E38: $732.000 | F38: $195.000 | G38: 0 | H38: $80.920.000 | I38: $9.000.000 | J38: $92.697.000
A39: GRANJA EXPERIMENTAL TODAS LAS SEDES | C39: 22 | D39: 0 | E39: 0 | F39: 0 | G39: 0 | H39: $18.210.000 | I39: $960.000 | J39: $19.170.000 | K39: Aprobadas en Consejo Académico
A42: AJUSTADO | C42: No. de solicitudes | D42: COMBUSTIBLE | E42: PEAJES | F42: PARQUEADERO | G42: IMPREVISTOS | H42: VALOR BUS EXTERNO | I42: COSTO TOTAL DÍAS VIATICOS DOCENTES | J42: TOTAL
C43: 161 | D43: ='TEORICO - PRACTICOS'!P162 -> 20490000 | E43: ='TEORICO - PRACTICOS'!Q162 -> 10174000 | F43: ='TEORICO - PRACTICOS'!R162 -> 2440000 | G43: ='TEORICO - PRACTICOS'!S162 -> 0 | H43: ='TEORICO - PRACTICOS'!T162 -> 350385000 | I43: ='TEORICO - PRACTICOS'!V162 -> 60836362 | J43: ='TEORICO - PRACTICOS'!W162 -> 444325362 | K43: =592159514-J43-19170000 -> 128664152 | L43: Reducción con los ajustes realizados
B47: TRAZABILIDAD
A49: 1. | B49: Mediante Circular de Programación No. 022 del 23 de mayo de 2022, se establecio como fecha limite el 5 de agosto para la remisión de las solicitudes de practicas extramuros con previa aval de los Consejos de Facultad
A50: 2. | B50: El 29 de agosto de 2022 mediante correo electrónico se envio a las Secretarías Académicas de las diferentes Facultad el consolidado de las prácticas extramuros y se solicito se revisarán las solicitudes con los respectivos Jefes de Programa, para poder dar tramite con el presupuesto disponible
A51: 3. | B51: Mediante Circular No. 038 del 4 de octubre de 2022, se solicitó nuevamente la revisión y ajuste de las solicitudes, teniendo en cuenta el presupuesto asignado
B53: Resultado de la Circular No. 038
...

Sheet TEORICO - PRACTICOS
A1: SEDE | B1: PROGRAMA | C1: NOMBRE DE LA PRACTICA | D1: NUMERO DEL CURSO | E1: CODIGO ALFANUMERICO | F1: NOMBRE DE LA ASIGNATURA | G1: NOMBRE DEL DOCENTE | H1: TIPO VINCULACIÓN DOCENTE | I1: FECHA INICIO (dÍa/mes/año) | J1: FECHA / FIN (dÍa/mes/año) | K1: RUTA | L1: DURAC. EN DIAS | M1: No. DE ALUMNOS | N1: OBSERVACIONES | O1: CONDUCTOR | P1: COMBUSTIBLE | Q1: PEAJES | R1: PARQUEADERO | S1: IMPREVISTOS | T1: VALOR BUS EXTERNO | U1: COSTO VALOR DÍA / DOCENTE | V1: COSTO TOTAL DÍAS VIATICOS DOCENTES | W1: TOTAL
A2: NEIVA | B2: CIENCIAS NATURALES -BIOLOGIA APLICADA | C2: ORIGEN DEL UNIVERSO- CONCEPTOS Y OBSERVACIONES | D2: 173832 | E2: BEBIAPL005 | F2: BIOLOGIA CELULAR 1 | G2: MAURICIO CARILLO AVILA | H2: DE PLANTA DOCENTE | I2: 44833 | J2: 44833 | K2: NEIVA.- VILLAVIEJA-NEIVA | L2: 1 | M2: 45 | T2: 1140000 | U2: 150000 | V2: =L2*U2 -> 150000
A3: NEIVA | B3: CIENCIAS NATURALES -BIOLOGIA APLICADA | C3: VISITA AL MUSEO DE HISTORIA NATURAL DE LA UNIVERSIDAD NACIONAL DE COLOMBIA Y TALLER EN LA FUNDACION ZOOLOGICO DE SANTA CRUZ - IMPORTANCIA DE ESTUDIOS"BOTANICOS MOLECULARES Y BIOTECNOLOGICOS" Y MANEJO DE MATERIAL VEGETAL EN JARDINES BOTANICOS Y HERBARIOS | D3: 173986 173983 173979 | E3: BEBIAPL049 | F3: PRINCIPIOS DE SISTEMATICA - BIOLOGIA DEL DESARROLLO - TAXONOMIA DE EMBRIOFITOS BASALES | G3: GUISELLE NEGOVER BRIÑEZ VASQUEZ/ CARLOS ALBERTO MENDEZ | H3: CATEDRA VISITANTE DOCENTE | I3: 44834 | J3: 44835 | K3: NEIVA-BOGOTA MUSEO DE HISTORIA NATURAL UNAL-SAN ANTONIO DEL TEQUENDAMA FUNDACION ZOOLOGICO DE SANTA CRUZ-NEIVA | L3: 2 | M3: =15+11+16 -> 42 | T3: 3960000 | U3: 150000 | V3: =L3*U3 -> 300000
A4: NEIVA | B4: CIENCIAS NATURALES -BIOLOGIA APLICADA | C4: ORIGEN DEL UNIVERSO- CONCEPTOS Y OBSERVACIONES | D4: 174483 | E4: BEBIAPL005 | F4: BIOLOGIA CELULAR 2 | G4: MAURICIO CARILLO AVILA | H4: DE PLANTA DOCENTE | I4: 44833 | J4: 44833 | K4: NEIVA.- VILLAVIEJA-NEIVA | L4: 1 | M4: 8 | T4: 420000 | U4: 150000 | V4: =L4*U4 -> 150000
A5: NEIVA | B5: CIENCIAS NATURALES -BIOLOGIA APLICADA | C5: IMPORTANCIA DE COLECCIONES BOTANICAS " JARDINES BOTANICOS Y HERBARIOS" | D5: 173835 | E5: BEBIAPL013 | F5: BOTANICA | G5: CARLOS ALBERTO MENDEZ PUENTES | H5: CATEDRA VISITANTE DOCENTE | I5: 44837 | J5: 44839 | K5: NEIVA-BOGOTA-MUSEODE HISTORIA NATURAL-HERBRIO UNIVERSIDAD NACIONAL DE COLOMBIA- JARDIN BOTANICO DE BOGOTA- NEIVA | L5: 3 | M5: 29 | O5: Desiderio Olarte | P5: 400000 | Q5: 180000 | R5: 50000 | U5: 150000 | V5: =L5*U5 -> 450000
A6: NEIVA | B6: CIENCIAS NATURALES -BIOLOGIA APLICADA | C6: VISITA CENTRO DE INVESTIGACION DE BOSQUE SECO TROPICAL-ATTALEA | D6: 174341 | E6: FEBIAPL020 | F6: VALORACION DE ECOSISTEMAS | G6: GUISELLE NEGOVER BRIÑEZ VASQUEZ | H6: CATEDRA VISITANTE DOCENTE | I6: 44837 | J6: 44837 | K6: NEIVA-AREA DE COMPESACION AMBIENTAL DE LA CENTRAL HIDROELECTRICA DEL QUIMBO EN LA VEREDA PEDERNAL DEL MUNICIPIO DE AGRADO-NEIVA | L6: 1 | M6: 21 | T6: 1290000 | U6: 150000 | V6: =L6*U6 -> 150000
A7: NEIVA | B7: CIENCIAS NATURALES -BIOLOGIA APLICADA | C7: ADAPTACION DE LOS INVERTEBRADOS A LAS CONDICIONES DE CAVERNA PARQUE NACIONAL NATURAL CUEVA DE LOS GUACHAROS | D7: 173843 | E7: BEBIAPL016 | F7: BIOLOGIA DE INVERTEBRADOS | G7: JUAN CARLOS VALENZUELA | H7: CATEDRA VISITANTE DOCENTE | I7: 44839 | J7: 44842 | K7: NEIVA-PALESTINA-VEREDA MENSURA-PARQUE NACIONAL CUEVA LOS GUACHAROS- NEIVA | L7: 4 | M7: 31 | O7: Alberto Mora | P7: 150000 | Q7: 41000 | R7: 45000 | U7: 150000 | V7: =L7*U7 -> 600000
A8: NEIVA | B8: CIENCIAS NATURALES -BIOLOGIA APLICADA | C8: ESTUDIO DE BIOLOGIA DE LA CONSERVACION | D8: 174836 | E8: BEBIAPL021 | F8: BIOLOGIA DE LA CONSERVACION | G8: EDGAR ANDRES BERNAL CATRO | H8: NOMBRAMIENTO OCASIONAL DOCENTE | I8: 44848 | J8: 44851 | K8: NEIVA-RESERVA JUANCHACO, MUNICIPIO DE BUENAVENTURA CHOCO- NEIVA | L8: 4 | M8: 19 | O8: Nelson Valbuena | P8: 600000 | Q8: 350000 | R8: 75000 | U8: 150000 | V8: =L8*U8 -> 600000
A9: NEIVA | B9: CIENCIAS NATURALES -BIOLOGIA APLICADA | C9: GESTION Y CONSERVACION DE ECOSISTEMAS ESTRATEGICOS - SISTEMAS AMBIENTALES DEL HUILA | D9: 174863 174854 | E9: FEBIAPL015 | F9: ECOSISTEMAS ESTRATEGICOS - SISTEMAS AMBIENTALES | G9: DIANA POLANIA CAVIEDES | H9: CATEDRA VISITANTE DOCENTE | I9: 44855 | J9: 44858 | K9: NEIVA-TESALIA-LA ARGENTINA-PITALITO-PARQUE NACIONAL NATURAL PURACE-NEIVA | L9: 3 | M9: =12+4 -> 16 | O9: Alberto Mora | P9: 150000 | Q9: 41000 | R9: 30000 | U9: 150000 | V9: =L9*U9 -> 450000
A10: NEIVA | B10: CIENCIAS NATURALES -BIOLOGIA APLICADA | C10: RECONOCIMIENTO DE LA DIVERSIDAD BIOLOGICA | D10: 174001 | E10: BEBIAPL028 | F10: GENETICA | G10: WILSON RODRIGO CRUZ FLOR | H10: CATEDRA VISITANTE DOCENTE | I10: 44860 | J10: 44862 | K10: NEIVA-LA TRIBUNA-NEIVA | L10: 2 | M10: 24 | T10: 3380000 | U10: 150000 | V10: =L10*U10 -> 300000
A11: NEIVA | B11: CIENCIAS NATURALES -BIOLOGIA APLICADA | C11: DIVERSIDAD DE VERTEBRADOS | D11: 173939 | E11: BEBIAPL012 | F11: BIOLOGIA DE VERTEBRADOS | G11: CAROLINA LOPEZ CASTAÑEDA | H11: NOMBRAMIENTO OCASIONAL DOCENTE | I11: 44870 | J11: 44872 | K11: NEIVA-SANTA MARIA- EL PARAISO-SAN BENITO-LA VEGA GUASIMOS-NEIVA | L11: 3 | M11: 35 | T11: 4500000 | U11: 150000 | V11: =L11*U11 -> 450000
A12: NEIVA | B12: CIENCIAS NATURALES -BIOLOGIA APLICADA | C12: ECOLOGIA Y ECOSISTEMAS - HISTORIA NATURAL DE LA TRANSFORMACION ECOLOGICA | D12: 173999 173996 | E12: BEEXnull01 | F12: ECOLOGIA - HISTORIA NATURAL | G12: DIANA POLANIA CAVIEDES/ EDGAR ANDRES BERNAL CASTRO | H12: CATEDRA VISITANTE DOCENTE | I12: 44877 | J12: 44880 | K12: NEIVA - BALSILLAS - NEIVA | L12: 3 | M12: 60 | T12: 7425000 | U12: 150000 | V12: =L12*U12 -> 450000
A13: NEIVA | B13: CIENCIAS NATURALES -BIOLOGIA APLICADA | C13: SISTEMA DE PRODUCCION ACUICOLA | D13: 174867 | E13: FEBIAPL016 | F13: PRODUCCION ACUICOLA | G13: RUBEN DARIO VALBUENA VILLAREAL | H13: DE PLANTA DOCENTE | I13: 44883 | J13: 44884 | K13: NEIVA- GARZON- NEIVA | L13: 2 | M13: 12 | O13: Desierio Olarte | P13: 0 | Q13: 20000 | R13: 10000 | U13: 150000 | V13: =L13*U13 -> 300000
A14: NEIVA | B14: CIENCIAS NATURALES -BIOLOGIA APLICADA | C14: RECONOCIMIENTO GEOLOGICO GENERAL SUR DE COLOMBIA | D14: 174862 | E14: BEBIAPL054 | F14: GEOCIENCIAS | G14: INGRID NATALIA MUÑOZ | H14: DE PLANTA DOCENTE | I14: 44889 | J14: 44892 | K14: NEIVA-POPAYAN (PASTO)- NEIVA | L14: 4 | M14: 18 | O14: Alberto Mora | P14: 600000 | Q14: 150000 | R14: 60000 | S14: 0 | T14: 0 | U14: 150000 | V14: =L14*U14 -> 600000
A15: NEIVA | B15: CIENCIAS NATURALES -BIOLOGIA APLICADA | C15: RECONOCIMIENTO DE ESPERMATOFICOS EN ECOSISTEMAS SURCOLOMBIANO | D15: 173995 | E15: BEBIAPL051 | F15: TAXONOMIA DE ESPERMATOFITOS | G15: CARLOS ALBERTO MENDEZ PUENTES | H15: CATEDRA VISITANTE DOCENTE | I15: 44890 | J15: 44892 | K15: NEIVA-PALESTINA-FINCA EL ENCANTO-CUEVA DE LOS GUACHAROS-NEIVA | L15: 3 | M15: 26 | O15: Alberto Mora | P15: 150000 | Q15: 41000 | R15: 20000 | U15: 150000 | V15: =L15*U15 -> 450000
A16: NEIVA | B16: CIENCIAS NATURALES -BIOLOGIA APLICADA | C16: ECOSISTEMAS ESTRATEGICOS Y PROBLEMATICAS | D16: 174855 174865 | E16: FEBIAPL003 | F16: PAISAJE ECOLOGICO - PROBLEMATICA ECOLOGICA Y AMBIENTAL | G16: RIGOBERTO MAYOR POLANIA | H16: CATEDRA VISITANTE DOCENTE | I16: 44889 | J16: 44891 | K16: NEIVA-AIPE RESERVAS NATURALES DE BOSQUE SECO TROPICAL- FUNDACION ASOBOSPA-NEIVA | L16: 3 | M16: 9 | O16: Alberto Mora | P16: 150000 | Q16: 32000 | R16: 20000 | U16: 150000 | V16: =L16*U16 -> 450000
A17: NEIVA | B17: CIENCIAS NATURALES -BIOLOGIA APLICADA | C17: CAMPO Y ECOLOGIA | D17: 174868 | E17: FEBIAPL030 | F17: ECOLOGIA DE CAMPO | G17: CARMEN ELENA BARRAGAN RUIZ | H17: CATEDRA VISITANTE DOCENTE | I17: 44897 | J17: 44901 | K17: VEREDA MEREMBERG | L17: 3 | M17: 16 | T17: 3540000 | U17: 150000 | V17: =L17*U17 -> 450000
A18: NEIVA | B18: ANTROPOLOGIA Y ARQUEOLOGIA | C18: ZONA DE VIDA,ECOSISTEMA TERRESTRES Y ACUATICOS, RECONOCIMIENTO DE FACTORES AMBIENTALES Y BIOTICOS, E INTERACCION CON LA COMUNIDAD HUMANA | D18: 172186 | E18: BECSHAN12 | F18: ECOLOGIA Y SOCIEDAD | G18: VLADYMEER LEON CUELLAR | H18: CATEDRA DOCENTE | I18: 44885 | J18: 44885 | K18: NEIVA-CUENCA HIDROGRAFICA RIO LAS CEIBAS | L18: 1 | M18: 7 | O18: Nelson Valbuena | P18: 0 | Q18: 0 | R18: 0 | U18: 150000 | V18: =L18*U18 -> 150000
A19: NEIVA | B19: ANTROPOLOGIA Y ARQUEOLOGIA | C19: INDUSTRIA TURISTICA Y CAMBIO SOCIOCULTURAL EN EL DESIERTO DE LA TATACOA | | D19: 172169-172166 | E19: BECSHAN06 BECSHAN05 | F19: PENSAMIENTO ANTROPOLOGICO I E INTRODUCCION A LA ARQUEOLOGIA | G19: LUIS GERARDO FRANCO ARCE Y LISANDRO SOTO FLECHAS | H19: CATEDRA VISITANTE DOCENTE | I19: 44874 | J19: 44876 | K19: NEIVA-MUNICIPIO DE VILLAVIEJA- DESIERTO LA TATACOA | L19: 3 | M19: =17+19 -> 36 | T19: 680000 | U19: 30000 | V19: =L19*U19 -> 90000
A20: NEIVA | B20: ANTROPOLOGIA Y ARQUEOLOGIA | C20: VICITA A HONDA, TOLIMA Y MUSEO DEL RIO MAGDALENA | D20: 172202-172199 | E20: BECSHAN17 BECSHAN16 | F20: ARQUEOLOGIA SOCIAL Y TEORIA SOCIAL I | G20: LUIS GERARDO FRANCO ARCE Y LISANDRO SOTO FLECHAS | H20: CATEDRA VISITANTE DOCENTE | I20: 44887 | J20: 44890 | K20: NEIVA,HUILA-HONDA,TOLIMA | L20: 4 | M20: =23+27 -> 50 | O20: Nelson Valbuena | P20: 400000 | Q20: 180000 | R20: 60000 | U20: 150000 | V20: =L20*U20 -> 600000
A21: NEIVA | B21: COMUNICACION SOCIAL Y PERIODISMO | C21: ACERCAMIENTO A LAS EXPERIENCIAS TRANSMEDIA | D21: 172808 | E21: BECSHCS28 | F21: LENGUAJE Y NARRATIVA TRANSMEDIA | G21: DIEGO FERNANDO ACHURRI SIERRA | H21: CATEDRA DOCENTE | I21: 44825 | J21: 44828 | K21: NEIVA-BOGOTA-NEIVA | L21: 4 | M21: 18 | O21: Desiderio Olarte | P21: 400000 | Q21: 180000 | R21: 60000 | U21: 150000 | V21: =L21*U21 -> 600000
A22: NEIVA | B22: COMUNICACION SOCIAL Y PERIODISMO | C22: NUEVAS FORMAS DE NARRAR | D22: 172790 | E22: BECSHCS19 | F22: COMINICACION DIGITAL | G22: DIEGO FERNANDO ACHURRI SIERRA | H22: CATEDRA DOCENTE | I22: 44872 | J22: 44874 | K22: NEIVA-MEDELLIN-NEIVA | L22: 3 | M22: 29 | O22: Alberto Mora | P22: 500000 | Q22: 270000 | R22: 50000 | U22: 150000 | V22: =L22*U22 -> 450000
A23: NEIVA | B23: COMUNICACION SOCIAL Y PERIODISMO | C23: HUILA AUDIOVISUAL | D23: 172778-172784 | E23: BECSHCS09 | F23: TALLER IMAGEN FIJA G01 Y G02 | G23: FERNANDO CHARRY GONZALEZ | H23: DE PLANTA DOCENTE | I23: 44876 | J23: 44878 | K23: VILLAVIEJA Y DESIERTO LA TATACOA | L23: 3 | M23: =21+20 -> 41 | T23: 1040000 | U23: 30000 | V23: =L23*U23 -> 90000
A24: PITALITO | B24: COMUNICACION SOCIAL Y PERIODISMO | C24: PROCESOS SOCIALES Y NARRATIVAS TRANSMEDIA EN CALI | D24: 172839 | E24: BECSHCS28 | F24: LENGUAJES Y NARRATIVAS TRANSMEDIA- SEDE PITALITO | G24: OSCAR IVAN FORERO MOSQUERA | H24: NOMBRAMIENTO OCASIONAL DOCENTE | I24: 44872 | J24: 44875 | K24: NEIVA-PITALITO-CALI( RECORRIDO INTERNO)-PITALITO-NEIVA | L24: 4 | M24: 17 | O24: Desiderio Olarte - Nelson Perdomo | P24: 500000 | Q24: 500000 | R24: 75000 | U24: 150000 | V24: =L24*U24 -> 600000
A25: PITALITO- NEIVA | B25: COMUNICACION SOCIAL Y PERIODISMO | C25: ARTICULACION DE CONTEXTOS LOCALES A PRODUCCION DE NARRATIVAS SONORAS Y AUDIOVISUALES EN PASTO | D25: 172803-172837 | E25: BECSHCS18 BECSHCS20 | F25: NARRATIVAS SONORAS Y AUDIOVISUALES (SEDE NEIVA)Y METODOLOGIAS PARA LA INTERACCION - SEDE PITALITO | G25: OSCAR IVAN FORERO MOSQUERA - CLAUDIA JIMENA ZUÑIGA RAMIREZ | H25: NOMBRAMIENTO OCASIONAL DOCENTE | I25: 44822 | J25: 44825 | K25: NEIVA-PITALITO-PASTO(RECORRIDO INTERNO Y VISITA AL LAGO DEL GUAMES)- PITALITO-NEIVA | L25: 4 | M25: =18+11 -> 29 | O25: Nelson Valbuena - Jairo Gonzalez | P25: 500000 | Q25: 150000 | R25: 60000 | U25: 150000 | V25: =L25*U25 -> 600000
A26: GARZON | B26: INGENIERÍA AGRÍCOLA | C26: APLICACION DE INDICADORES PARA EL ANALISIS DE LA CALIDAD DEL AGAUA EN LA QUBRADA RIO LORO-GARZON | D26: 174798 | E26: BEEXTA12 | F26: CALIDAD DE AGUAS | G26: KAREN DANIELA QUINTERO | H26: CATEDRA VISITANTE DOCENTE | I26: 44847 | J26: 44848 | K26: QUEBRADA RIO LORO DESDE ZULUAGA HASTA EL POBLADO DE RIO LORO | L26: 2 | M26: 15 | N26: NO TIENE FORMATO MI-FOR-FO-16 | T26: 1020000
A27: GARZON | B27: INGENIERÍA AGRÍCOLA | C27: CARACTERISTICAS MORFOMETRICAS Y GEOMORFOLOGICAS DE UNA CUENCA HIDROGRAFICA | D27: 174641 | E27: BEINAG83 | F27: MANEJO DE CUENCAS HIDROGRAFICAS | G27: ALEXANDRA LUNA CUELLAR | H27: CATEDRA DOCENTE | I27: 44867 | J27: 44869 | K27: SALIDA DE GARZON-MANIZALEZ-PARQUE LOS NEVADOS-GARZON | L27: 3 | M27: 8 | N27: NO TIENE FORMATO MI-FOR-FO-16 | T27: 8400000 | U27: 150000 | V27: =L27*U27 -> 450000
A28: GARZON | B28: INGENIERÍA AGRÍCOLA | C28: PROCESO DE PRODUCCION, COSECHA, POST-COSECHA, INDUSTRIALIZACION Y COMERCIALIZACION DEL CAFE | D28: 174645 | E28: FEINAG79 | F28: TECNOLOGIA DEL CAFE | G28: LUIS FERNANDO CALDERON ALVARADO | H28: CATEDRA VISITANTE DOCENTE | I28: 44869 | J28: 44870 | K28: GARZON-EL PITAL- LA PLATA-GIGANTE-GARZON | L28: 2 | M28: 17 | N28: NO TIENE FORMATO MI-FOR-FO-16 | T28: 3120000 | U28: 150000 | V28: =L28*U28 -> 300000
A29: GARZON | B29: INGENIERÍA AGRÍCOLA | C29: DETERMINACION DE LAS PRINCIPALES PROPIEDADES MECANICAS DE LOS MATERIALES. ENSAYO DE TRACCION | D29: 174600 | E29: BEINAG12 | F29: ELEMENTOS DE MAQUINAS | G29: JUAN CARLOS MARTINEZ WALLES | H29: CATEDRA VISITANTE DOCENTE | I29: 44872 | J29: 44872 | K29: SEDE PRINCIPAL UNIVERSIDAD SURCOLOBIANA , LABORATORIO DE MATERIALES, GARZON-NEIVA-GARZON | L29: 2 | M29: 23 | O29: Nelson Valbuena | P29: 150000 | Q29: 40000 | R29: 0 | U29: 150000 | V29: =L29*U29 -> 300000
A30: GARZON | B30: INGENIERÍA AGRÍCOLA | C30: ANATOMIA EXTERNA DEL ALTO, MORFOLOGIA DE LA RAIZ, PROPIEDADES FISCIO QUIMICAS DEL AGUA, POTENCIAL HIDRICO IMBIHICION PERMEABILIDAD DE | D30: 174627 | E30: BEINAG02 | F30: FISIOLOGIA VEGETAL | G30: ERNETH PARRA MENDEZ | H30: CATEDRA VISITANTE DOCENTE | I30: 44873 | J30: 44873 | K30: GARZON-LABORATORIO FISIOLOGIA VEGETAL DE LA UNIVERSIDAD SURCOLOMBIANA, SEDE PITALITO-GARZON | L30: 1 | M30: 9 | O30: Nelson Valbuena | P30: 150000 | Q30: 41000 | R30: 0 | U30: 150000 | V30: =L30*U30 -> 150000
A31: GARZON | B31: INGENIERÍA AGRÍCOLA | C31: DESARROLLO SOSTENIBLE EN TORNO A LA FINCA AGROECOÑOGICA | D31: 174601 | E31: FEINAG64 | F31: DESARROLLO SOSTENIBLE Y MEDIO AMBIENTE | G31: MARTHA LUCIA PEÑA QUIMBAYA | H31: CATEDRA DOCENTE | I31: 44874 | J31: 44877 | K31: LA PLATA-GARZON-BOGOTA-RESTREPO VIA AL LLANO-GARZON- LA PLATA | L31: 2 | M31: 7 | N31: NO TIENE FORMATO MI-FOR-FO-16 | T31: 6620000 | U31: 150000 | V31: =L31*U31 -> 300000
A32: GARZON | B32: INGENIERÍA AGRÍCOLA | C32: POTENCIA EN QUIPOS AGRICOLAS, EQUPOS DE LABRANZA, CAPACIDAD DE TRABAJO Y PERFILES DEL CIRTE DE LOS IMPLEMENTOS AGRICOLAS | D32: 174447 | E32: BEINAG19 | F32: MAQUINAS AGRICOLAS | G32: JUAN CARLOS MARTINEZ WALLES | H32: CATEDRA VISITANTE DOCENTE | I32: 44876 | J32: 44876 | K32: GARZON-AIPE-GARZON | L32: 1 | M32: 10 | T32: 1200000 | U32: 150000 | V32: =L32*U32 -> 150000
A33: GARZON | B33: INGENIERÍA AGRÍCOLA | C33: PRACTICA INTEGRAL DE LABORATORIO FISICA MECANICA | D33: 174619 | E33: BFEXCN06 | F33: FISICA MECANICA | G33: WILLIAM ARLED SANCHEZ VARGAS | H33: CATEDRA VISITANTE DOCENTE | I33: 44876 | J33: 44876 | K33: GARZON VIA NACIONAL A PITALITO SEDE USCO-PITALITO-GARZON | L33: 1 | M33: 9 | T33: 1560000 | U33: 150000 | V33: =L33*U33 -> 150000
A34: GARZON | B34: INGENIERÍA AGRÍCOLA | C34: ESTRUCTURAS DE CLIMA CONTROLADO | D34: 174602 | E34: FEINGAGR84 | F34: DISEÑO Y CONSTRUCCION DE INVERNADEROS | G34: LUIS FERNANDO CALDERON ALVARADO | H34: CATEDRA VISITANTE DOCENTE | I34: 44876 | J34: 44877 | K34: GARZON-GIGANTE-ESPINAL-EL JUNCAL-GARZON | L34: 2 | M34: 12 | N34: NO TIENE FORMATO MI-FOR-FO-16 | T34: 1190000 | U34: 150000 | V34: =L34*U34 -> 300000
A35: GARZON | B35: INGENIERÍA AGRÍCOLA | C35: LABORATORIO MECANICA DE SUELOS | D35: 174323 | E35: BFINAG05 | F35: MECANICA DE SUELOS | G35: ERNETH PARRA MENDEZ | H35: CATEDRA VISITANTE DOCENTE | I35: 44876 | J35: 44876 | K35: UNIVERSIDAD SURCOLOMBIANA GARZON-UNIVERSIDAD SURCOLOMBIANA NEIVA | L35: 1 | M35: 11 | N35: NO TIENE FORMATO MI-FOR-FO-16 | T35: 1260000 | U35: 150000 | V35: =L35*U35 -> 150000
A36: GARZON | B36: INGENIERÍA AGRÍCOLA | C36: PRACTICA INTEGRAL DE MATERIALES DE CONTRUCCION, ELABORACION PROBETAS DE CONCRETO, DIERÑO DE MEZCLAS, GRANULOMETRIA, DENSIDAD APARENTE Y REAL PARA GRANOS GRUESOS Y FINOS, ENTRE OTRAS PRUEBAS BASICAS | D36: 174456 | E36: BEINAG20 | F36: MATERIALES DE CONSTRUCCION | G36: JOSE AGENER ZAPATA | H36: CATEDRA VISITANTE DOCENTE | I36: 44878 | J36: 44878 | K36: GARZON-NEIVA USCO SEDE CENTRAL-LABORATORIO DE MATERIALES-GARZON | L36: 1 | M36: 17 | O36: Nelson Valbuena | P36: 150000 | Q36: 40000 | R36: 0 | U36: 150000 | V36: =L36*U36 -> 150000
A37: GARZON | B37: INGENIERÍA AGRÍCOLA | C37: PRACTICA INTEGRAL | D37: 174459 | E37: BEINAG21 | F37: PRACTICA INTEGRAL | G37: JOSE AGENER ZAPATA | H37: CATEDRA VISITANTE DOCENTE | I37: 44880 | J37: 44883 | K37: GARZON- GINEBRA-PALMIRA-LA UNION-TULUA-VALENCIA-BUGA-GARZON | L37: 4 | M37: 17 | N37: NO TIENE FORMATO MI-FOR-FO-16 | T37: 12720000 | U37: 150000 | V37: =L37*U37 -> 600000
A38: GARZON | B38: INGENIERÍA AGRÍCOLA | C38: EVALUACION DE PARAMETROS Y METODOS DE RIEGO Y CARACTERIZACION DE UN DISTRITO DE RIEGO DE GRAN ESCALA | D38: 174438 | E38: BEINAG17 | F38: INGENIERIA DE RIEGOS I | G38: CARLOS CÁCERES GONZALEZ | H38: CATEDRA VISITANTE DOCENTE | I38: 44881 | J38: 44881 | K38: SALIDA DEL MUNICIPIO DE GARZON HACIA EL MUNICIPIO DEL ESPINAL, TOLIMA, DISTRITO DE RIEGO USOCOELLO-REGRESO AL MUNICIPIO DE GARZON | L38: 1 | M38: 22 | N38: NO TIENE FORMATO MI-FOR-FO-16 | T38: 1890000 | U38: 150000 | V38: =L38*U38 -> 150000
A39: GARZON | B39: INGENIERÍA AGRÍCOLA | C39: IDENTIFICACION DE LOS FACTORES Y PROCESOS QUE INCIDEN EN EL MANEJO Y CONSERVACION DE PRODUCTOS AGROPECUARIOS | D39: 174430 | E39: BEINAG15 | F39: MANEJO Y CONSERVACION DE PRODUCTOS AGROPECUARIOS | G39: OSCAR MAURICIO BERMEO | H39: NOMBRAMIENTO OCASIONAL DOCENTE | I39: 44881 | J39: 44883 | K39: GARZON-NEIVA (CESUCAFE-AGROINDUTRIA)- RIVERA (EMPRESA CACAO RIVERENSE)-PITALITO (TECNOPARQUE YAMBORÓ-CERVECERIA ARTESANAL)-TARQUI (QUESOS REYMA)-GARZON | L39: 3 | M39: 18 | N39: NO TIENE FORMATO MI-FOR-FO-16 | T39: 2400000 | U39: 150000 | V39: =L39*U39 -> 450000
A40: GARZON | B40: INGENIERÍA AGRÍCOLA | C40: DISTRITOS DE RIEGO EN EL TOLIMA, GRANJAS INTEGRALES EN FUSA, MUSEO IGAC, MUSEO GEOLOGICO COLOMBIANO, LABORATORIOS DE SUELOS UNIVERSIDAD NACIONAL AREA DE VIVEROS E | D40: 174399 | E40: BEINAG24 | F40: SUELOS | G40: ERNETH PARRA MENDEZ | H40: CATEDRA VISITANTE DOCENTE | I40: 44881 | J40: 44883 | K40: GARZON-FOSFATOS DEL HUILA, DISTRITOS DE RIEGO EN EL TOLIMA,GRANJAS INTEGRALES EN FUSA, MUSEO IGAC, MUSEO GEOLOGICO COLOMBIANO, LABORATORIO DE SUELOS UNIVERSIDAD NACIONAL REA DE VIVIEROS E | L40: 3 | M40: 16 | T40: 10350000 | U40: 150000 | V40: =L40*U40 -> 450000
...
